Workbook

Sheet Overview
A1: Sr | B1: MODULE | C1: DESCRIPTION | D1: REQUIRED | E1: PRIORITY | F1: COMMENTS
A2: PATIENT MOBILE APP (native iOS & Android)
A3: 1 | B3: Onboarding & consent | C3: Account creation, identity verification, two-factor login, and plain-language consent captured before any data is collected. | D3: Yes | E3: Must Have
A4: 2 | B4: Intake & goals | C4: An AI-guided intake gathers goals, history and habits, then proposes goals the patient selects — which stay pending physician approval. | D4: Yes | E4: Must Have
A5: 3 | B5: Data connections | C5: The patient authorizes their EMR (across multiple hospitals), connects wearables via Terra, and uploads outside lab or DEXA reports. | D5: Yes | E5: Must Have
A6: 4 | B6: Dashboard & record | C6: A near-real-time home screen showing overall and domain scores, trends, the longitudinal record, and all biomarkers on gauges. | D6: Yes | E6: Must Have
A7: 5 | B7: Optimization report | C7: The interpretive quarterly report — released only after physician sign-off — with per-marker gauges, lifestyle-vs-physician guidance, and data provenance. | D7: Yes | E7: Must Have
A8: 6 | B8: Plan & tasks | C8: The patient's daily and weekly lifestyle plan, with morning and evening check-ins and adherence logging. | D8: Yes | E8: Must Have
A9: 7 | B9: AI copilot (chat) | C9: A guarded assistant grounded in the patient's own data — answering wellness questions by text or voice, routing clinical questions to the physician, and redirecting emergencies to urgent care. | D9: Yes | E9: Must Have
A10: 8 | B10: Messages, coaching, purchases | C10: Secure care-team messaging, coaching booking, and management of membership, add-on panels and AI usage. | D10: Yes | E10: Must Have
A11: PHYSICIAN / PRACTICE PORTAL (web)
A12: 1 | B12: Roster & referral | C12: The practice's patient roster with enrollment, physician assignment, patient referral, and invitation. | D12: Yes | E12: Must Have
A13: 2 | B13: Priority queue | C13: A work queue that sorts patients by clinical rule severity, change magnitude and recency so the physician sees what needs attention first. | D13: Yes | E13: Must Have
A14: 3 | B14: One-page summary & record | C14: A single-screen patient summary plus the full longitudinal record with provenance, and a pre-visit brief of changes since the last visit. | D14: Yes | E14: Must Have
A15: 4 | B15: AI copilot | C15: A physician-facing copilot that surfaces biomarker trends, flags findings, suggests follow-up tests, and highlights panel-level gaps. | D15: Yes | E15: Must Have
A16: 5 | B16: Report review & sign-off | C16: Where the physician reviews the AI-drafted report and approves, edits, rejects or requests a repeat test — sign-off releases it to the patient. | D16: Yes | E16: Must Have
A17: 6 | B17: Plan builder | C17: Tools to set goals, interventions, monitoring cadence and success measures, and to approve the patient's goals. | D17: Yes | E17: Must Have
A18: 7 | B18: Alerts & safety | C18: Alert detail with triggering data, rule version and confidence, and the workflow to acknowledge and route abnormal findings. | D18: Yes | E18: Must Have
A19: 8 | B19: Billing & admin | C19: Practice billing and revenue-share visibility, plus user, role and permission management. | D19: Yes | E19: Must Have
A20: 9 | B20: Practice dashboard | C20: A practice-scoped analytics view of enrollment, engagement, outcomes, physician review time and renewal-supporting metrics. | D20: Yes | E20: Must Have
A21: COACH PORTAL
A22: 1 | B22: Access | C22: Secure login with MFA and tightly scoped access — coaches see only wellness data for their assigned patients, never the clinical record. | D22: Yes | E22: Must Have
A23: 2 | B23: Patient context | C23: The coach's view of each assigned patient's physician-approved goals, lifestyle plan and adherence. | D23: Yes | E23: Must Have
A24: 3 | B24: Scheduling | C24: Tools for the coach to view and manage coaching sessions and set their availability. | D24: Yes | E24: Must Have
A25: 4 | B25: Messaging | C25: Secure messaging with assigned patients, kept within the wellness boundary — no clinical advice. | D25: Yes | E25: Must Have
A26: 5 | B26: Session notes | C26: Recording and reviewing coaching session notes per patient. | D26: Yes | E26: Must Have
A27: HOL TEAM PORTAL (web)
A28: 1 | B28: Clinical content — biomarker catalog | C28: Maintaining the 125-biomarker catalog, keeping lab range, physician target and HOL optimal range as three separate fields. | D28: Yes | E28: Must Have
A29: 2 | B29: Clinical content — protocols & rules | C29: Authoring and versioning the protocol/SOP library and configuring the alert rules and score weights the engine uses. | D29: Yes | E29: Must Have
A30: 3 | B30: Clinical content — evaluation harness | C30: A library of graded clinical test cases that every AI change is regression-tested against, with prompt/model versions logged. | D30: Yes | E30: Must Have
A31: 4 | B31: Operations — integration health | C31: Monitoring the health of EMR, Terra and partner connections, and surfacing and retrying failed imports. | D31: Yes | E31: Must Have
A32: 5 | B32: Operations — parsing review | C32: A verification queue where HOL staff review and correct low-confidence document extractions before they enter the record. | D32: Yes | E32: Must Have
A33: 6 | B33: Operations — consent, audit, tenancy | C33: Consent status per patient, the immutable audit trail, and tenant and security administration. | D33: Yes | E33: Must Have
A34: 7 | B34: Back office & catalog | C34: Managing the add-on catalog and pricing, tracking partner commissions, and administering usage, billing and revenue-share. | D34: Yes | E34: Must Have
A35: 8 | B35: Analytics dashboards | C35: HOL-wide, cross-practice dashboards for engagement, outcomes, care gaps and program value. | D35: Yes | E35: Must Have
A36: SHARED BACKEND (spans all portals)
A37: 1 | B37: LHOR / longitudinal record | C37: The normalization pipeline and time-series database that turn every source into one comparable per-patient record, plus the document store and full data model. | D37: Yes | E37: Must Have
A38: 2 | B38: AI intelligence layer | C38: Retrieval on a commercial model with orchestration, grounding, report and digest generation, the guarded chat and physician copilot, guardrails and the evaluation harness. | D38: Yes | E38: Must Have
A39: 3 | B39: CRM / care orchestration | C39: The workflow engine running the care loop, physician sign-off routing, abnormal-finding routing, engagement automation, scoring and the alert/rules engine. | D39: Yes | E39: Must Have
A40: 4 | B40: Identity & multi-tenancy | C40: Authentication for all roles, role-based access control, and isolation of each practice's data as its own tenant. | D40: Yes | E40: Must Have
...

Sheet Deviation 30-10-2026
A1: Module | B1: Sub-module | C1: Status | D1: Description | E1: Required | F1: FE | G1: BE | H1: Approved
A2: SECTION A: NEW AND MODIFIED FEATURES BY PORTAL
A3: SUPER ADMIN PORTAL
A4: Super Admin Portal: New Features
A5: =TRIM('Super Admin Portal Hol Portal'!A10) | B5: =IFERROR(__xludf.DUMMYFUNCTION("IFERROR(TEXTJOIN("", "",TRUE,UNIQUE(FILTER(TRIM('Super Admin Portal Hol Portal'!B11:B22),'Super Admin Portal Hol Portal'!E11:E22=""New""))),"""")"),"Navigation, Dashboard") | C5: New | D5: =IFERROR(__xludf.DUMMYFUNCTION("IFERROR(TEXTJOIN(CHAR(10),TRUE,FILTER(""• ""&TRIM('Super Admin Portal Hol Portal'!C11:C22),'Super Admin Portal Hol Portal'!E11:E22=""New"")),"""")"),"• Navigation & Notifications • Global Search • Dashboard Filters • Summary Cards • Enrolment by State • Invites & Conversion • Patient Status & Enrolment Funnel • Practices on Inlay • Region Table") | E5: Yes | F5: =SUMIFS('Super Admin Portal Hol Portal'!G11:G22,'Super Admin Portal Hol Portal'!E11:E22,"New") | G5: =SUMIFS('Super Admin Portal Hol Portal'!H11:H22,'Super Admin Portal Hol Portal'!E11:E22,"New")
A6: =TRIM('Super Admin Portal Hol Portal'!A23) | B6: =IFERROR(__xludf.DUMMYFUNCTION("IFERROR(TEXTJOIN("", "",TRUE,UNIQUE(FILTER(TRIM('Super Admin Portal Hol Portal'!B24:B41),'Super Admin Portal Hol Portal'!E24:E41=""New""))),"""")"),"Clinical Content, Catalog, Rules, Eval") | C6: New | D6: =IFERROR(__xludf.DUMMYFUNCTION("IFERROR(TEXTJOIN(CHAR(10),TRUE,FILTER(""• ""&TRIM('Super Admin Portal Hol Portal'!C24:C41),'Super Admin Portal Hol Portal'!E24:E41=""New"")),"""")"),"• Clinical Content Overview • Range List • Sex/Age Rule List • Alert Rule List • Test-Case List") | E6: Yes | F6: =SUMIFS('Super Admin Portal Hol Portal'!G24:G41,'Super Admin Portal Hol Portal'!E24:E41,"New") | G6: =SUMIFS('Super Admin Portal Hol Portal'!H24:H41,'Super Admin Portal Hol Portal'!E24:E41,"New")
A7: =TRIM('Super Admin Portal Hol Portal'!A42) | B7: =IFERROR(__xludf.DUMMYFUNCTION("IFERROR(TEXTJOIN("", "",TRUE,UNIQUE(FILTER(TRIM('Super Admin Portal Hol Portal'!B43:B54),'Super Admin Portal Hol Portal'!E43:E54=""New""))),"""")"),"Settings, AI, Partners") | C7: New | D7: =IFERROR(__xludf.DUMMYFUNCTION("IFERROR(TEXTJOIN(CHAR(10),TRUE,FILTER(""• ""&TRIM('Super Admin Portal Hol Portal'!C43:C54),'Super Admin Portal Hol Portal'!E43:E54=""New"")),"""")"),"• Settings Overview • AI Credit Allowance • Partner List • Add & Edit Partner") | E7: Yes | F7: =SUMIFS('Super Admin Portal Hol Portal'!G43:G54,'Super Admin Portal Hol Portal'!E43:E54,"New") | G7: =SUMIFS('Super Admin Portal Hol Portal'!H43:H54,'Super Admin Portal Hol Portal'!E43:E54,"New")
A8: =TRIM('Super Admin Portal Hol Portal'!A55) | B8: =IFERROR(__xludf.DUMMYFUNCTION("IFERROR(TEXTJOIN("", "",TRUE,UNIQUE(FILTER(TRIM('Super Admin Portal Hol Portal'!B56:B60),'Super Admin Portal Hol Portal'!E56:E60=""New""))),"""")"),"Practice List, Practice Details") | C8: New | D8: =IFERROR(__xludf.DUMMYFUNCTION("IFERROR(TEXTJOIN(CHAR(10),TRUE,FILTER(""• ""&TRIM('Super Admin Portal Hol Portal'!C56:C60),'Super Admin Portal Hol Portal'!E56:E60=""New"")),"""")"),"• Practice List • Practice Overview • Edit & Deactivate Practice • Providers & Users") | E8: Yes | F8: =SUMIFS('Super Admin Portal Hol Portal'!G56:G60,'Super Admin Portal Hol Portal'!E56:E60,"New") | G8: =SUMIFS('Super Admin Portal Hol Portal'!H56:H60,'Super Admin Portal Hol Portal'!E56:E60,"New")
A9: =TRIM('Super Admin Portal Hol Portal'!A67) | B9: =IFERROR(__xludf.DUMMYFUNCTION("IFERROR(TEXTJOIN("", "",TRUE,UNIQUE(FILTER(TRIM('Super Admin Portal Hol Portal'!B68:B80),'Super Admin Portal Hol Portal'!E68:E80=""New""))),"""")"),"Billing") | C9: New | D9: =IFERROR(__xludf.DUMMYFUNCTION("IFERROR(TEXTJOIN(CHAR(10),TRUE,FILTER(""• ""&TRIM('Super Admin Portal Hol Portal'!C68:C80),'Super Admin Portal Hol Portal'!E68:E80=""New"")),"""")"),"• Billing Dashboard • Test & Imaging Catalogue • Price & Margin Calculation • Membership & AI Allowance • Practice Billing Terms • Practice Invoices • Sales Tax") | E9: Yes | F9: =SUMIFS('Super Admin Portal Hol Portal'!G68:G80,'Super Admin Portal Hol Portal'!E68:E80,"New") | G9: =SUMIFS('Super Admin Portal Hol Portal'!H68:H80,'Super Admin Portal Hol Portal'!E68:E80,"New")
D10: Subtotal: Super Admin Portal: New Features | F10: =SUM(F5:F9) | G10: =SUM(G5:G9)
A12: Super Admin Portal: Modified Features (delta hours)
A13: =TRIM('Super Admin Portal Hol Portal'!A23) | B13: =IFERROR(__xludf.DUMMYFUNCTION("IFERROR(TEXTJOIN("", "",TRUE,UNIQUE(FILTER(TRIM('Super Admin Portal Hol Portal'!B24:B41),'Super Admin Portal Hol Portal'!E24:E41=""Modified""))),"""")"),"Catalog, Rules") | C13: Modified | D13: =IFERROR(__xludf.DUMMYFUNCTION("IFERROR(TEXTJOIN(CHAR(10),TRUE,FILTER(""• ""&TRIM('Super Admin Portal Hol Portal'!C24:C41)&"": ""&TRIM('Super Admin Portal Hol Portal'!D24:D41),'Super Admin Portal Hol Portal'!E24:E41=""Modified"")),"""")"),"• Biomarker definitions: As a clinical admin, I can maintain biomarker definitions and canonical units by adding, editing, search, filter and retiring biomarkers. • Alert rules: As a clinical admin, I can configure the deterministic safety/priority rules "&"by adding and editing rules and turning each one on or off.") | E13: Yes | F13: =SUMIFS('Super Admin Portal Hol Portal'!G24:G41,'Super Admin Portal Hol Portal'!E24:E41,"Modified")-8 | G13: =SUMIFS('Super Admin Portal Hol Portal'!H24:H41,'Super Admin Portal Hol Portal'!E24:E41,"Modified")-12
A14: =TRIM('Super Admin Portal Hol Portal'!A55) | B14: =IFERROR(__xludf.DUMMYFUNCTION("IFERROR(TEXTJOIN("", "",TRUE,UNIQUE(FILTER(TRIM('Super Admin Portal Hol Portal'!B56:B60),'Super Admin Portal Hol Portal'!E56:E60=""Modified""))),"""")"),"Tenancy") | C14: Modified | D14: =IFERROR(__xludf.DUMMYFUNCTION("IFERROR(TEXTJOIN(CHAR(10),TRUE,FILTER(""• ""&TRIM('Super Admin Portal Hol Portal'!C56:C60)&"": ""&TRIM('Super Admin Portal Hol Portal'!D56:D60),'Super Admin Portal Hol Portal'!E56:E60=""Modified"")),"""")"),"• Tenant admin: As a Super Admin, I should be able to add a practice (a new tenant) with its details, contact, location, messaging number and the features it can use.") | E14: Yes | F14: =SUMIFS('Super Admin Portal Hol Portal'!G56:G60,'Super Admin Portal Hol Portal'!E56:E60,"Modified")-2 | G14: =SUMIFS('Super Admin Portal Hol Portal'!H56:H60,'Super Admin Portal Hol Portal'!E56:E60,"Modified")-4
A15: =TRIM('Super Admin Portal Hol Portal'!A67) | B15: =IFERROR(__xludf.DUMMYFUNCTION("IFERROR(TEXTJOIN("", "",TRUE,UNIQUE(FILTER(TRIM('Super Admin Portal Hol Portal'!B68:B80),'Super Admin Portal Hol Portal'!E68:E80=""Modified""))),"""")"),"Billing") | C15: Modified | D15: =IFERROR(__xludf.DUMMYFUNCTION("IFERROR(TEXTJOIN(CHAR(10),TRUE,FILTER(""• ""&TRIM('Super Admin Portal Hol Portal'!C68:C80)&"": ""&TRIM('Super Admin Portal Hol Portal'!D68:D80),'Super Admin Portal Hol Portal'!E68:E80=""Modified"")),"""")"),"• Refunds & adjustments: As HOL ops, I can issue refunds to the original payment method, apply credits for orders that didn’t complete, and make billing adjustments. • Billing reports: As HOL ops, I can produce billing and revenue reports, including vendo"&"r payouts, revenue by lab and imaging, cancellation and late-fee losses, overdue practices, and totals by channel.") | E15: Yes | F15: =SUMIFS('Super Admin Portal Hol Portal'!G68:G80,'Super Admin Portal Hol Portal'!E68:E80,"Modified")-4 | G15: =SUMIFS('Super Admin Portal Hol Portal'!H68:H80,'Super Admin Portal Hol Portal'!E68:E80,"Modified")-8
D16: Subtotal: Super Admin Portal: Modified Features (delta hours) | F16: =SUM(F13:F15) | G16: =SUM(G13:G15)
A18: PHYSICIAN PORTAL
A19: Physician Portal: New Features
A20: =TRIM('Physician Portal Provider port'!A3) | B20: =IFERROR(__xludf.DUMMYFUNCTION("IFERROR(TEXTJOIN("", "",TRUE,UNIQUE(FILTER(TRIM('Physician Portal Provider port'!B4:B9),'Physician Portal Provider port'!E4:E9=""New""))),"""")"),"Invitation, Activate Account, Forgot Password") | C20: New | D20: =IFERROR(__xludf.DUMMYFUNCTION("IFERROR(TEXTJOIN(CHAR(10),TRUE,FILTER(""• ""&TRIM('Physician Portal Provider port'!C4:C9),'Physician Portal Provider port'!E4:E9=""New"")),"""")"),"• Invitation Email • Two-Factor Setup • Forgot Password & Reset Code") | E20: Yes | F20: =SUMIFS('Physician Portal Provider port'!G4:G9,'Physician Portal Provider port'!E4:E9,"New") | G20: =SUMIFS('Physician Portal Provider port'!H4:H9,'Physician Portal Provider port'!E4:E9,"New")
A21: =TRIM('Physician Portal Provider port'!A10) | B21: =IFERROR(__xludf.DUMMYFUNCTION("IFERROR(TEXTJOIN("", "",TRUE,UNIQUE(FILTER(TRIM('Physician Portal Provider port'!B11:B19),'Physician Portal Provider port'!E11:E19=""New""))),"""")"),"Dashboard, Worklist") | C21: New | D21: =IFERROR(__xludf.DUMMYFUNCTION("IFERROR(TEXTJOIN(CHAR(10),TRUE,FILTER(""• ""&TRIM('Physician Portal Provider port'!C11:C19),'Physician Portal Provider port'!E11:E19=""New"")),"""")"),"• My Tasks • Today’s Schedule • Abnormal Results") | E21: Yes | F21: =SUMIFS('Physician Portal Provider port'!G11:G19,'Physician Portal Provider port'!E11:E19,"New") | G21: =SUMIFS('Physician Portal Provider port'!H11:H19,'Physician Portal Provider port'!E11:E19,"New")
A22: =TRIM('Physician Portal Provider port'!A20) | B22: =IFERROR(__xludf.DUMMYFUNCTION("IFERROR(TEXTJOIN("", "",TRUE,UNIQUE(FILTER(TRIM('Physician Portal Provider port'!B21:B33),'Physician Portal Provider port'!E21:E33=""New""))),"""")"),"Add Patient, Edit Patient, Bulk Add Patients, Patients") | C22: New | D22: =IFERROR(__xludf.DUMMYFUNCTION("IFERROR(TEXTJOIN(CHAR(10),TRUE,FILTER(""• ""&TRIM('Physician Portal Provider port'!C21:C33),'Physician Portal Provider port'!E21:E33=""New"")),"""")"),"• Add Patient Form • Duplicate Patient Check • Edit Patient • Template & Upload • Add bulk patient • Tabs, Search, Filters & Pagination • Select & Export") | E22: Yes | F22: =SUMIFS('Physician Portal Provider port'!G21:G33,'Physician Portal Provider port'!E21:E33,"New") | G22: =SUMIFS('Physician Portal Provider port'!H21:H33,'Physician Portal Provider port'!E21:E33,"New")
A23: =TRIM('Physician Portal Provider port'!A34) | B23: =IFERROR(__xludf.DUMMYFUNCTION("IFERROR(TEXTJOIN("", "",TRUE,UNIQUE(FILTER(TRIM('Physician Portal Provider port'!B35:B39),'Physician Portal Provider port'!E35:E39=""New""))),"""")"),"Tasks, Add Task") | C23: New | D23: =IFERROR(__xludf.DUMMYFUNCTION("IFERROR(TEXTJOIN(CHAR(10),TRUE,FILTER(""• ""&TRIM('Physician Portal Provider port'!C35:C39),'Physician Portal Provider port'!E35:E39=""New"")),"""")"),"• Task List • Tabs, Search, Filter • Select Tasks • Bulk Mark Complete • Add Task") | E23: Yes | F23: =SUMIFS('Physician Portal Provider port'!G35:G39,'Physician Portal Provider port'!E35:E39,"New") | G23: =SUMIFS('Physician Portal Provider port'!H35:H39,'Physician Portal Provider port'!E35:E39,"New")
A24: =TRIM('Physician Portal Provider port'!A40) | B24: =IFERROR(__xludf.DUMMYFUNCTION("IFERROR(TEXTJOIN("", "",TRUE,UNIQUE(FILTER(TRIM('Physician Portal Provider port'!B41:B44),'Physician Portal Provider port'!E41:E44=""New""))),"""")"),"Scheduling") | C24: New | D24: =IFERROR(__xludf.DUMMYFUNCTION("IFERROR(TEXTJOIN(CHAR(10),TRUE,FILTER(""• ""&TRIM('Physician Portal Provider port'!C41:C44),'Physician Portal Provider port'!E41:E44=""New"")),"""")"),"• Appointments – Calendar View • Appointments – List View • Appointment Details & Filters") | E24: Yes | F24: =SUMIFS('Physician Portal Provider port'!G41:G44,'Physician Portal Provider port'!E41:E44,"New") | G24: =SUMIFS('Physician Portal Provider port'!H41:H44,'Physician Portal Provider port'!E41:E44,"New")
A25: =TRIM('Physician Portal Provider port'!A45) | B25: =IFERROR(__xludf.DUMMYFUNCTION("IFERROR(TEXTJOIN("", "",TRUE,UNIQUE(FILTER(TRIM('Physician Portal Provider port'!B46:B54),'Physician Portal Provider port'!E46:E54=""New""))),"""")"),"Communication, New Chat") | C25: New | D25: =IFERROR(__xludf.DUMMYFUNCTION("IFERROR(TEXTJOIN(CHAR(10),TRUE,FILTER(""• ""&TRIM('Physician Portal Provider port'!C46:C54),'Physician Portal Provider port'!E46:E54=""New"")),"""")"),"• Conversation List • Search & Filter Conversations • Conversation View • Send Message • Voice to Text • Attach & Share Documents • Reply to a Message • Reactions • Start New Chat") | E25: Yes | F25: =SUMIFS('Physician Portal Provider port'!G46:G54,'Physician Portal Provider port'!E46:E54,"New") | G25: =SUMIFS('Physician Portal Provider port'!H46:H54,'Physician Portal Provider port'!E46:E54,"New")
A26: =TRIM('Physician Portal Provider port'!A71) | B26: =IFERROR(__xludf.DUMMYFUNCTION("IFERROR(TEXTJOIN("", "",TRUE,UNIQUE(FILTER(TRIM('Physician Portal Provider port'!B72:B103),'Physician Portal Provider port'!E72:E103=""New""))),"""")"),"Patient Header, Dashboard, Overview, Care Plan, Encounters, Appointments, Diagnoses, Medications, Allergies, Patient Chart") | C26: New | D26: =IFERROR(__xludf.DUMMYFUNCTION("IFERROR(TEXTJOIN(CHAR(10),TRUE,FILTER(""• ""&TRIM('Physician Portal Provider port'!C72:C103),'Physician Portal Provider port'!E72:E103=""New"")),"""")"),"• Patient Header • Add patient Label • Important Updates • Face Sheet • Print Chart • Timeline • Edit Plan • Plan History • Revise Plan • Encounter List • Encounter view • Print & Download Encounter • Appointments • Diagnosis List • Diagnosis Details • Me"&"dications • Allergies • Vitals – Card View • Vitals – Trend View • Vitals – Table View • Lab Reports • Lab Orders • Add Lab Order • Family History • Patient Profile • Discharge or Deactivate Patient") | E26: Yes | F26: =SUMIFS('Physician Portal Provider port'!G72:G103,'Physician Portal Provider port'!E72:E103,"New") | G26: =SUMIFS('Physician Portal Provider port'!H72:H103,'Physician Portal Provider port'!E72:E103,"New")
A27: =TRIM('Physician Portal Provider port'!A110) | B27: =IFERROR(__xludf.DUMMYFUNCTION("IFERROR(TEXTJOIN("", "",TRUE,UNIQUE(FILTER(TRIM('Physician Portal Provider port'!B111:B117),'Physician Portal Provider port'!E111:E117=""New""))),"""")"),"Billing, Orders") | C27: New | D27: =IFERROR(__xludf.DUMMYFUNCTION("IFERROR(TEXTJOIN(CHAR(10),TRUE,FILTER(""• ""&TRIM('Physician Portal Provider port'!C111:C117),'Physician Portal Provider port'!E111:E117=""New"")),"""")"),"• Invoice Details • Pay Invoice & Raise Query • Order a Test • Order Details") | E27: Yes | F27: =SUMIFS('Physician Portal Provider port'!G111:G117,'Physician Portal Provider port'!E111:E117,"New") | G27: =SUMIFS('Physician Portal Provider port'!H111:H117,'Physician Portal Provider port'!E111:E117,"New")
A28: =TRIM('Physician Portal Provider port'!A118) | B28: =IFERROR(__xludf.DUMMYFUNCTION("IFERROR(TEXTJOIN("", "",TRUE,UNIQUE(FILTER(TRIM('Physician Portal Provider port'!B119:B125),'Physician Portal Provider port'!E119:E125=""New""))),"""")"),"Provider Account, Notifications, Security") | C28: New | D28: =IFERROR(__xludf.DUMMYFUNCTION("IFERROR(TEXTJOIN(CHAR(10),TRUE,FILTER(""• ""&TRIM('Physician Portal Provider port'!C119:C125),'Physician Portal Provider port'!E119:E125=""New"")),"""")"),"• Patient Flags • Notification preferences • Audit Log") | E28: Yes | F28: =SUMIFS('Physician Portal Provider port'!G119:G125,'Physician Portal Provider port'!E119:E125,"New") | G28: =SUMIFS('Physician Portal Provider port'!H119:H125,'Physician Portal Provider port'!E119:E125,"New")
A29: =TRIM('Physician Portal Provider port'!B126) | B29: =IFERROR(__xludf.DUMMYFUNCTION("IFERROR(TEXTJOIN("", "",TRUE,UNIQUE(FILTER(TRIM('Physician Portal Provider port'!B127:B131),'Physician Portal Provider port'!E127:E131=""New""))),"""")"),"Dashboard") | C29: New | D29: =IFERROR(__xludf.DUMMYFUNCTION("IFERROR(TEXTJOIN(CHAR(10),TRUE,FILTER(""• ""&TRIM('Physician Portal Provider port'!C127:C131),'Physician Portal Provider port'!E127:E131=""New"")),"""")"),"• Enrollment & activation • Engagement metrics • Outcome changes • Alert volume • Value & renewal metrics") | E29: Yes | F29: =SUMIFS('Physician Portal Provider port'!G127:G131,'Physician Portal Provider port'!E127:E131,"New") | G29: =SUMIFS('Physician Portal Provider port'!H127:H131,'Physician Portal Provider port'!E127:E131,"New")
A30: =TRIM('Physician Portal Provider port'!A132) | B30: =IFERROR(__xludf.DUMMYFUNCTION("IFERROR(TEXTJOIN("", "",TRUE,UNIQUE(FILTER(TRIM('Physician Portal Provider port'!B133:B140),'Physician Portal Provider port'!E133:E140=""New""))),"""")"),"Users, Providers, Provider, Non-clinical Users") | C30: New | D30: =IFERROR(__xludf.DUMMYFUNCTION("IFERROR(TEXTJOIN(CHAR(10),TRUE,FILTER(""• ""&TRIM('Physician Portal Provider port'!C133:C140),'Physician Portal Provider port'!E133:E140=""New"")),"""")"),"• Search, Filter • Bulk Add Providers • Add Provider • Provider Profile • Provider Bulk Import – CSV Import History • Edit Provider • Non-clinical Users List • Add User") | E30: Yes | F30: =SUMIFS('Physician Portal Provider port'!G133:G140,'Physician Portal Provider port'!E133:E140,"New") | G30: =SUMIFS('Physician Portal Provider port'!H133:H140,'Physician Portal Provider port'!E133:E140,"New")
A31: =TRIM('Physician Portal Provider port'!A141) | B31: =IFERROR(__xludf.DUMMYFUNCTION("IFERROR(TEXTJOIN("", "",TRUE,UNIQUE(FILTER(TRIM('Physician Portal Provider port'!B142:B146),'Physician Portal Provider port'!E142:E146=""New""))),"""")"),"Locations, Add Location, Location Details") | C31: New | D31: =IFERROR(__xludf.DUMMYFUNCTION("IFERROR(TEXTJOIN(CHAR(10),TRUE,FILTER(""• ""&TRIM('Physician Portal Provider port'!C142:C146),'Physician Portal Provider port'!E142:E146=""New"")),"""")"),"• Location List • Search, Filter • Add Location • Location Details • Edit Location") | E31: Yes | F31: =SUMIFS('Physician Portal Provider port'!G142:G146,'Physician Portal Provider port'!E142:E146,"New") | G31: =SUMIFS('Physician Portal Provider port'!H142:H146,'Physician Portal Provider port'!E142:E146,"New")
A32: =TRIM('Physician Portal Provider port'!A147) | B32: =IFERROR(__xludf.DUMMYFUNCTION("IFERROR(TEXTJOIN("", "",TRUE,UNIQUE(FILTER(TRIM('Physician Portal Provider port'!B148:B153),'Physician Portal Provider port'!E148:E153=""New""))),"""")"),"Provider Account, Employer Accounts, Patient Invitation, Notifications, Security") | C32: New | D32: =IFERROR(__xludf.DUMMYFUNCTION("IFERROR(TEXTJOIN(CHAR(10),TRUE,FILTER(""• ""&TRIM('Physician Portal Provider port'!C148:C153),'Physician Portal Provider port'!E148:E153=""New"")),"""")"),"• Patient Flags • Employer List & Add Employer • Invitation Channels • Invitation Reminders • Notification preferences • Audit Log") | E32: Yes | F32: =SUMIFS('Physician Portal Provider port'!G148:G153,'Physician Portal Provider port'!E148:E153,"New") | G32: =SUMIFS('Physician Portal Provider port'!H148:H153,'Physician Portal Provider port'!E148:E153,"New")
D33: Subtotal: Physician Portal: New Features | F33: =SUM(F20:F32) | G33: =SUM(G20:G32)
A35: Physician Portal: Modified Features (delta hours)
A36: =TRIM('Physician Portal Provider port'!A10) | B36: =IFERROR(__xludf.DUMMYFUNCTION("IFERROR(TEXTJOIN("", "",TRUE,UNIQUE(FILTER(TRIM('Physician Portal Provider port'!B11:B19),'Physician Portal Provider port'!E11:E19=""Modified""))),"""")"),"Dashboard") | C36: Modified | D36: =IFERROR(__xludf.DUMMYFUNCTION("IFERROR(TEXTJOIN(CHAR(10),TRUE,FILTER(""• ""&TRIM('Physician Portal Provider port'!C11:C19)&"": ""&TRIM('Physician Portal Provider port'!D11:D19),'Physician Portal Provider port'!E11:E19=""Modified"")),"""")"),"• Alert volume: As a Provider, I should see one list of items waiting on me and act on each one directly (review, open or reply).") | E36: Yes | F36: =SUMIFS('Physician Portal Provider port'!G11:G19,'Physician Portal Provider port'!E11:E19,"Modified")-2 | G36: =SUMIFS('Physician Portal Provider port'!H11:H19,'Physician Portal Provider port'!E11:E19,"Modified")-4
A37: =TRIM('Physician Portal Provider port'!A20) | B37: =IFERROR(__xludf.DUMMYFUNCTION("IFERROR(TEXTJOIN("", "",TRUE,UNIQUE(FILTER(TRIM('Physician Portal Provider port'!B21:B33),'Physician Portal Provider port'!E21:E33=""Modified""))),"""")"),"Patient") | C37: Modified | D37: =IFERROR(__xludf.DUMMYFUNCTION("IFERROR(TEXTJOIN(CHAR(10),TRUE,FILTER(""• ""&TRIM('Physician Portal Provider port'!C21:C33)&"": ""&TRIM('Physician Portal Provider port'!D21:D33),'Physician Portal Provider port'!E21:E33=""Modified"")),"""")"),"• Patient list: As a Provider, I should see my practice’s patients with risk level, ID, name, age and bio age, contact, location, primary provider, status, last interaction and last sync, and open a patient’s dashboard from the list.") | E37: Yes | F37: =SUMIFS('Physician Portal Provider port'!G21:G33,'Physician Portal Provider port'!E21:E33,"Modified")-4 | G37: =SUMIFS('Physician Portal Provider port'!H21:H33,'Physician Portal Provider port'!E21:E33,"Modified")-6
A38: =TRIM('Physician Portal Provider port'!A40) | B38: =IFERROR(__xludf.DUMMYFUNCTION("IFERROR(TEXTJOIN("", "",TRUE,UNIQUE(FILTER(TRIM('Physician Portal Provider port'!B41:B44),'Physician Portal Provider port'!E41:E44=""Modified""))),"""")"),"Scheduling") | C38: Modified | D38: =IFERROR(__xludf.DUMMYFUNCTION("IFERROR(TEXTJOIN(CHAR(10),TRUE,FILTER(""• ""&TRIM('Physician Portal Provider port'!C41:C44)&"": ""&TRIM('Physician Portal Provider port'!D41:D44),'Physician Portal Provider port'!E41:E44=""Modified"")),"""")"),"• Appointments view: As a physician, I can view appointments pulled from the EHR by day, week or month, as a calendar or a list, move between dates (Today, previous, next) and see the appointment count, with filters (type, status, in-person/virtual); view"&" only.") | E38: Yes | F38: =SUMIFS('Physician Portal Provider port'!G41:G44,'Physician Portal Provider port'!E41:E44,"Modified")-2 | G38: =SUMIFS('Physician Portal Provider port'!H41:H44,'Physician Portal Provider port'!E41:E44,"Modified")-2
A39: =TRIM('Physician Portal Provider port'!A71) | B39: =IFERROR(__xludf.DUMMYFUNCTION("IFERROR(TEXTJOIN("", "",TRUE,UNIQUE(FILTER(TRIM('Physician Portal Provider port'!B72:B103),'Physician Portal Provider port'!E72:E103=""Modified""))),"""")"),"AI Chart Summary, Patient Chart/ details") | C39: Modified | D39: =IFERROR(__xludf.DUMMYFUNCTION("IFERROR(TEXTJOIN(CHAR(10),TRUE,FILTER(""• ""&TRIM('Physician Portal Provider port'!C72:C103)&"": ""&TRIM('Physician Portal Provider port'!D72:D103),'Physician Portal Provider port'!E72:E103=""Modified"")),"""")"),"• Trends & flags: As a Provider, I should see the patient’s out-of-range results and trends to watch, each with its latest value and a mini trend. • sticky notes: As a Provider, I should see the patient’s sticky note count with the latest note, and be abl"&"e to add a note.") | E39: Yes | F39: =SUMIFS('Physician Portal Provider port'!G72:G103,'Physician Portal Provider port'!E72:E103,"Modified")-14 | G39: =SUMIFS('Physician Portal Provider port'!H72:H103,'Physician Portal Provider port'!E72:E103,"Modified")-14
A40: =TRIM('Physician Portal Provider port'!A110) | B40: =IFERROR(__xludf.DUMMYFUNCTION("IFERROR(TEXTJOIN("", "",TRUE,UNIQUE(FILTER(TRIM('Physician Portal Provider port'!B111:B117),'Physician Portal Provider port'!E111:E117=""Modified""))),"""")"),"Billing") | C40: Modified | D40: =IFERROR(__xludf.DUMMYFUNCTION("IFERROR(TEXTJOIN(CHAR(10),TRUE,FILTER(""• ""&TRIM('Physician Portal Provider port'!C111:C117)&"": ""&TRIM('Physician Portal Provider port'!D111:D117),'Physician Portal Provider port'!E111:E117=""Modified"")),"""")"),"• Practice Invoices: As a Clinic Manager, I can see my practice’s invoices for every month and download the statment and pay for it.") | E40: Yes | F40: =SUMIFS('Physician Portal Provider port'!G111:G117,'Physician Portal Provider port'!E111:E117,"Modified")-2 | G40: =SUMIFS('Physician Portal Provider port'!H111:H117,'Physician Portal Provider port'!E111:E117,"Modified")-2
D41: Subtotal: Physician Portal: Modified Features (delta hours) | F41: =SUM(F36:F40) | G41: =SUM(G36:G40)
A43: PATIENT APP
A44: Patient App: New Features
...

Sheet Portal Deviation
A1: Portal deviation: 18 Sep 2026 scope vs 30 Oct 2026 scope (hours = FE + BE)
A3: Portal | B3: Retained hrs | C3: Modified hrs (18 Sep) | D3: Removed hrs | E3: Covered hrs | F3: Original scope hrs (18 Sep) | G3: New hrs added (+) | H3: Modified change hrs (+/-) | I3: Removed + Covered hrs (-) | J3: Net change hrs | K3: Current scope hrs (30 Oct) | L3: % added (New / Original) | M3: % removed ((Removed + Covered) / Original) | N3: Net deviation %
A4: Super Admin Portal | B4: =SUMIFS('Super Admin Portal Hol Portal'!G3:G84,'Super Admin Portal Hol Portal'!E3:E84,"Retained")+SUMIFS('Super Admin Portal Hol Portal'!H3:H84,'Super Admin Portal Hol Portal'!E3:E84,"Retained") | C4: 38 | D4: =SUMIFS('Super Admin Portal Hol Portal'!G3:G84,'Super Admin Portal Hol Portal'!E3:E84,"Removed")+SUMIFS('Super Admin Portal Hol Portal'!H3:H84,'Super Admin Portal Hol Portal'!E3:E84,"Removed") | E4: =SUMIFS('Super Admin Portal Hol Portal'!G3:G84,'Super Admin Portal Hol Portal'!E3:E84,"Covered")+SUMIFS('Super Admin Portal Hol Portal'!H3:H84,'Super Admin Portal Hol Portal'!E3:E84,"Covered") | F4: =B4+C4+D4+E4 | G4: =SUMIFS('Super Admin Portal Hol Portal'!G3:G84,'Super Admin Portal Hol Portal'!E3:E84,"New")+SUMIFS('Super Admin Portal Hol Portal'!H3:H84,'Super Admin Portal Hol Portal'!E3:E84,"New") | H4: =SUMIFS('Super Admin Portal Hol Portal'!G3:G84,'Super Admin Portal Hol Portal'!E3:E84,"Modified")+SUMIFS('Super Admin Portal Hol Portal'!H3:H84,'Super Admin Portal Hol Portal'!E3:E84,"Modified")-C4 | I4: =D4+E4 | J4: =G4+H4-I4 | K4: =F4+J4 | L4: =IF(F4=0,0,G4/F4) | M4: =IF(F4=0,0,I4/F4) | N4: =IF(F4=0,0,J4/F4)
A5: Physician Portal | B5: =SUMIFS('Physician Portal Provider port'!G3:G153,'Physician Portal Provider port'!E3:E153,"Retained")+SUMIFS('Physician Portal Provider port'!H3:H153,'Physician Portal Provider port'!E3:E153,"Retained") | C5: 52 | D5: =SUMIFS('Physician Portal Provider port'!G3:G153,'Physician Portal Provider port'!E3:E153,"Removed")+SUMIFS('Physician Portal Provider port'!H3:H153,'Physician Portal Provider port'!E3:E153,"Removed") | E5: =SUMIFS('Physician Portal Provider port'!G3:G153,'Physician Portal Provider port'!E3:E153,"Covered")+SUMIFS('Physician Portal Provider port'!H3:H153,'Physician Portal Provider port'!E3:E153,"Covered") | F5: =B5+C5+D5+E5 | G5: =SUMIFS('Physician Portal Provider port'!G3:G153,'Physician Portal Provider port'!E3:E153,"New")+SUMIFS('Physician Portal Provider port'!H3:H153,'Physician Portal Provider port'!E3:E153,"New") | H5: =SUMIFS('Physician Portal Provider port'!G3:G153,'Physician Portal Provider port'!E3:E153,"Modified")+SUMIFS('Physician Portal Provider port'!H3:H153,'Physician Portal Provider port'!E3:E153,"Modified")-C5 | I5: =D5+E5 | J5: =G5+H5-I5 | K5: =F5+J5 | L5: =IF(F5=0,0,G5/F5) | M5: =IF(F5=0,0,I5/F5) | N5: =IF(F5=0,0,J5/F5)
A6: Patient App | B6: =SUMIFS('Patient App'!G3:G151,'Patient App'!E3:E151,"Retained")+SUMIFS('Patient App'!H3:H151,'Patient App'!E3:E151,"Retained") | C6: 12 | D6: =SUMIFS('Patient App'!G3:G151,'Patient App'!E3:E151,"Removed")+SUMIFS('Patient App'!H3:H151,'Patient App'!E3:E151,"Removed") | E6: =SUMIFS('Patient App'!G3:G151,'Patient App'!E3:E151,"Covered")+SUMIFS('Patient App'!H3:H151,'Patient App'!E3:E151,"Covered") | F6: =B6+C6+D6+E6 | G6: =SUMIFS('Patient App'!G3:G151,'Patient App'!E3:E151,"New")+SUMIFS('Patient App'!H3:H151,'Patient App'!E3:E151,"New") | H6: =SUMIFS('Patient App'!G3:G151,'Patient App'!E3:E151,"Modified")+SUMIFS('Patient App'!H3:H151,'Patient App'!E3:E151,"Modified")-C6 | I6: =D6+E6 | J6: =G6+H6-I6 | K6: =F6+J6 | L6: =IF(F6=0,0,G6/F6) | M6: =IF(F6=0,0,I6/F6) | N6: =IF(F6=0,0,J6/F6)
A7: Coach Portal | B7: =SUMIFS('Coach Portal'!H3:H21,'Coach Portal'!G3:G21,"Retained")+SUMIFS('Coach Portal'!I3:I21,'Coach Portal'!G3:G21,"Retained") | C7: 0 | D7: =SUMIFS('Coach Portal'!H3:H21,'Coach Portal'!G3:G21,"Removed")+SUMIFS('Coach Portal'!I3:I21,'Coach Portal'!G3:G21,"Removed") | E7: =SUMIFS('Coach Portal'!H3:H21,'Coach Portal'!G3:G21,"Covered")+SUMIFS('Coach Portal'!I3:I21,'Coach Portal'!G3:G21,"Covered") | F7: =B7+C7+D7+E7 | G7: =SUMIFS('Coach Portal'!H3:H21,'Coach Portal'!G3:G21,"New")+SUMIFS('Coach Portal'!I3:I21,'Coach Portal'!G3:G21,"New") | H7: =SUMIFS('Coach Portal'!H3:H21,'Coach Portal'!G3:G21,"Modified")+SUMIFS('Coach Portal'!I3:I21,'Coach Portal'!G3:G21,"Modified")-C7 | I7: =D7+E7 | J7: =G7+H7-I7 | K7: =F7+J7 | L7: =IF(F7=0,0,G7/F7) | M7: =IF(F7=0,0,I7/F7) | N7: 0
A8: Shared Backend Layers | B8: =SUMIFS('Shared Backend Layers'!H3:H101,'Shared Backend Layers'!G3:G101,"Retained")+SUMIFS('Shared Backend Layers'!I3:I101,'Shared Backend Layers'!G3:G101,"Retained") | C8: 0 | D8: =SUMIFS('Shared Backend Layers'!H3:H101,'Shared Backend Layers'!G3:G101,"Removed")+SUMIFS('Shared Backend Layers'!I3:I101,'Shared Backend Layers'!G3:G101,"Removed") | E8: =SUMIFS('Shared Backend Layers'!H3:H101,'Shared Backend Layers'!G3:G101,"Covered")+SUMIFS('Shared Backend Layers'!I3:I101,'Shared Backend Layers'!G3:G101,"Covered") | F8: =B8+C8+D8+E8 | G8: =SUMIFS('Shared Backend Layers'!H3:H101,'Shared Backend Layers'!G3:G101,"New")+SUMIFS('Shared Backend Layers'!I3:I101,'Shared Backend Layers'!G3:G101,"New") | H8: =SUMIFS('Shared Backend Layers'!H3:H101,'Shared Backend Layers'!G3:G101,"Modified")+SUMIFS('Shared Backend Layers'!I3:I101,'Shared Backend Layers'!G3:G101,"Modified")-C8 | I8: =D8+E8 | J8: =G8+H8-I8 | K8: =F8+J8 | L8: =IF(F8=0,0,G8/F8) | M8: =IF(F8=0,0,I8/F8) | N8: 0
A9: Total (all portals) | B9: =SUM(B4:B8) | C9: =SUM(C4:C8) | D9: =SUM(D4:D8) | E9: =SUM(E4:E8) | F9: =SUM(F4:F8) | G9: =SUM(G4:G8) | H9: =SUM(H4:H8) | I9: =SUM(I4:I8) | ... K9: =SUM(K4:K8) | L9: =IF(F9=0,0,G9/F9) | M9: =IF(F9=0,0,I9/F9) | N9: =IF(F9=0,0,J9/F9)

Sheet Super Admin Portal  Hol Portal
G1: =SUM(G3:G84) | H1: =SUM(H3:H84)
A2: SR.NO | B2: MODULE | C2: CAPABILITY | D2: USER STORY | E2: STATUS | F2: REQUIRED | G2: FRONT END | H2: BACK END | I2: DESIGN LINK | J2: COMMENT
A3: Login
B4: Invitation | C4: Invitation Email | D4: As a Super Admin, I should receive an invitation email from the platform admin who invited me, with my role, my email, a one-time activation code and an “Activate account” button, so that I can activate my account. | E4: Retained | F4: Yes | G4: 2 | H4: 2 | I4: Prototype Link
B5: Activate Account | C5: Activate Account & Set Password | D5: As a Super Admin, I should be able to activate my account with the code from my email and create my password. | E5: Retained | F5: Yes | G5: 2 | H5: 2 | I5: Prototype Link
B6: Activate Account | C6: Two-Factor Setup | D6: As a Super Admin, I should be able to set up two-factor authentication with an authenticator app so that my account is protected. | E6: Retained | F6: Yes | G6: 2 | H6: 2 | I6: Prototype Link
B7: Sign In | C7: Sign In | D7: As a Super Admin, I should be able to sign in to the admin console with my Organization ID, email and password, with an option to remember me on the same device. | E7: Retained | F7: Yes | G7: 2 | H7: 2 | I7: Prototype Link
B8: Sign In | C8: Two-Factor Verification | D8: As a Super Admin, I should enter a code from my authenticator app to complete sign-in when asked (once a week and on a new device). | E8: Retained | F8: Yes | G8: 2 | H8: 2 | I8: Prototype Link
B9: Forgot Password | C9: Forgot & Reset Password | D9: As a Super Admin, I want to reset my password with a code sent to my email so that I can get back into my account if I forget it. | E9: Retained | F9: Yes | G9: 2 | H9: 2 | I9: Prototype Link
A10: DASHBOARDS
B11: Dashboard | C11: Engagement & outcomes | D11: As a HOL analyst, I can view cohort, engagement and outcome dashboards. | E11: Retained | F11: Yes | G11: 4 | H11: 6 | I11: Prototype Link
B12: Dashboard | C12: Care-gap view | D12: As a HOL analyst, I can view care gaps across a panel. | E12: Removed | F12: Yes | G12: 2 | H12: 4
B13: Dashboard | C13: Practice value & renewal | D13: As a HOL analyst, I can view value and renewal-supporting metrics. | E13: Removed | F13: Yes | G13: 4 | H13: 6
B14: Navigation | C14: Navigation & Notifications | D14: As a Super Admin, I should be able to move between Dashboard, Practices and Settings from a collapsible side menu, and view my notifications from the bell icon. | E14: New | F14: Yes | G14: 2 | H14: 2 | I14: Prototype Link
B15: Navigation | C15: Global Search | D15: As a Super Admin, I should be able to search across the admin console from the top bar. | E15: New | F15: Yes | G15: 2 | H15: 4 | I15: Prototype Link
B16: Dashboard | C16: Dashboard Filters | D16: As a Super Admin, I should be able to filter the dashboard by date range (preset or custom) and by all regions or one region. | E16: New | F16: Yes | G16: 2 | H16: 2 | I16: Prototype Link
B17: Dashboard | C17: Summary Cards | D17: As a Super Admin, I should see the number of users onboarded, providers onboarded and patients enrolled, each against its total with the percentage. | E17: New | F17: Yes | G17: 2 | H17: 2 | I17: Prototype Link
B18: Dashboard | C18: Enrolment by State | D18: As a Super Admin, I should see enrolment across the US on a map by state status, with an enrolment summary and the three highest and three lowest regions. | E18: New | F18: Yes | G18: 4 | H18: 2 | I18: Prototype Link
B19: Dashboard | C19: Invites & Conversion | D19: As a Super Admin, I should see invites sent, patients enrolled and the conversion rate, with a weekly chart of invites against enrolments. | E19: New | F19: Yes | G19: 2 | H19: 2 | I19: Prototype Link
B20: Dashboard | C20: Patient Status & Enrolment Funnel | D20: As a Super Admin, I should see how many patients are enrolled, pending or declined, and the enrolment funnel from invited to answered to enrolled. | E20: New | F20: Yes | G20: 2 | H20: 2 | I20: Prototype Link
B21: Dashboard | C21: Practices on Inlay | D21: As a Super Admin, I should see the total number of practices, how many were added in the selected period, and a chart of practices added over time. | E21: New | F21: Yes | G21: 2 | H21: 2 | I21: Prototype Link
B22: Dashboard | C22: Region Table | D22: As a Super Admin, I should view each region’s practices, providers, patients, enrolment counts and enrolment rate, listed from lowest to highest rate. | E22: New | F22: Yes | G22: 4 | H22: 2 | I22: Prototype Link
A23: CLINICAL CONTENT CONSOLE
B24: Clinical Content | C24: Clinical Content Overview | D24: As a super admin, I should see all clinical content areas (catalog, protocols, rules, forecast, eval and evidence) in one place and open any of them. | E24: New | G24: 2 | H24: 2 | I24: Prototype Link
B25: Catalog | C25: Biomarker definitions | D25: As a clinical admin, I can maintain biomarker definitions and canonical units by adding, editing, search, filter and retiring biomarkers. | E25: Modified | F25: Yes | G25: 4 | H25: 6 | I25: Prototype Link
B26: Catalog | C26: Range management | D26: As a clinical admin, I can set lab range, physician target, and HOL optimal range separately. | E26: Retained | F26: Yes | G26: 4 | H26: 6 | I26: Prototype Link
B27: Catalog | C27: Range List | D27: As a clinical admin, I should see each biomarker’s unit, lab range, physician target and Inlay optimal range in one list, and search, filter, select and export it. | E27: New | G27: 2 | H27: 2 | I27: Prototype Link
B28: Catalog | C28: Sex/age rules | D28: As a clinical admin, I can set sex/age display and scoring rules by adding, editing and deleting them. | E28: Retained | F28: Yes | G28: 2 | H28: 4 | I28: Prototype Link
B29: Catalog | C29: Sex/Age Rule List | D29: As a clinical admin, I should see all sex and age rules with the biomarker, sex, age, ranges, display and scoring for each, and search, filter them. | E29: New | G29: 2 | H29: 2 | I29: Prototype Link
B30: Protocols | C30: Author protocols | D30: As the Medical Director, I can author protocols and SOPs. | E30: Removed | F30: Yes | G30: 4 | H30: 6
B31: Protocols | C31: Versioning | D31: As the Medical Director, I can version the library with source citations. | E31: Removed | F31: Yes | G31: 4 | H31: 6
B32: Protocols | C32: Approval workflow | D32: As the Medical Director, I can approve content before it goes live. | E32: Removed | F32: Yes | G32: 2 | H32: 4
B33: Rules | C33: Alert rules | D33: As a clinical admin, I can configure the deterministic safety/priority rules by adding and editing rules and turning each one on or off. | E33: Modified | F33: Yes | G33: 4 | H33: 6 | I33: Prototype Link
B34: Rules | C34: Alert Rule List | D34: As a clinical admin, I should see all alert rules with their condition, priority, action and whether each is on, and search, filter. | E34: New | G34: 2 | H34: 2 | I34: Prototype Link
B35: Rules | C35: Score weights | D35: As a clinical admin, I can set overall/domain score weights and algorithm version. | E35: Removed | F35: Yes | G35: 4 | H35: 6
B36: Forecast | C36: Forecast thresholds | D36: As a clinical admin, I can set forecast confidence thresholds and minimum data points. | E36: Removed | F36: Yes | G36: 2 | H36: 4
B37: Eval | C37: Test-case library | D37: As the Medical Director, I can author graded clinical test cases. (Immaging and lab order) | E37: Retained | F37: Yes | G37: 4 | H37: 6 | I37: Prototype Link
B38: Eval | C38: Test-Case List | D38: As the Medical Director, I should see all clinical test cases with their area, severity, expected outcome and latest result, and search, filter, select and export them. | E38: New | G38: 2 | H38: 2 | I38: Prototype Link
B39: Eval | C39: Regression gate | D39: As an engineer, a change is regression-tested before it ships. | E39: Removed | F39: Yes | G39: 2 | H39: 6
B40: Eval | C40: Version log | D40: As an engineer, prompt/model/protocol versions are logged for reproducibility. | E40: Removed | F40: Yes | G40: 2 | H40: 4
...

Sheet Physician Portal  Provider port
G1: =SUM(G3:G153) | H1: =SUM(H3:H153)
A2: SR.NO | B2: MODULE | C2: CAPABILITY | D2: USER STORY | E2: STATUS | F2: REQUIRED | G2: FRONT END | H2: BACK END | I2: DESIGN LINK | J2: COMMENT
A3: Provider Onboarding & Login
B4: Auth | C4: Login & MFA | D4: As a Provider, I should be able to sign in with my Organization ID, email and password, with an option to remember me on the same device, and enter a code from my authenticator app to complete sign-in when asked (once a week and on a new device). | E4: Retained | F4: Yes | G4: 2 | H4: 2 | I4: Prototype Link
B5: Onboarding | C5: Practice onboarding | D5: As an admin, I can onboard the practice and its physicians. | E5: Retained | F5: Yes | G5: 4 | H5: 6 | I5: Prototype Link
B6: Invitation | C6: Invitation Email | D6: As a Provider, I should receive an invitation email from my practice’s clinic manager with my role, my email, a one-time activation code and an “Activate account” button, so that I can join the provider portal. | E6: New | F6: Yes | G6: 2 | H6: 2 | I6: Prototype Link
B7: Activate Account | C7: Activate Account & Set Password | D7: As a Provider, I should be able to activate my account with the code from my email and create my password. | E7: Retained | F7: Yes | G7: 2 | H7: 2 | I7: Prototype Link
B8: Activate Account | C8: Two-Factor Setup | D8: As a Provider, I should be able to set up two-factor authentication with an authenticator app so that my account is protected. | E8: New | F8: Yes | G8: 2 | H8: 2 | I8: Prototype Link
B9: Forgot Password | C9: Forgot Password & Reset Code | D9: As a Provider, I should be able to request a password reset code to my email, verify it, and resend it if I didn’t receive it. | E9: New | F9: Yes | G9: 2 | H9: 2 | I9: Prototype Link
A10: Dashboard
B11: Dashboard | C11: Enrollment & activation | D11: As a practice admin, I can see patient enrollment and activation metrics. | E11: Retained | F11: Yes | G11: 4 | H11: 6 | I11: Prototype Link
B12: Dashboard | C12: Engagement metrics | D12: As a practice admin, I can see patient engagement across my panel. | E12: Removed | F12: Yes | G12: 2 | H12: 4
B13: Dashboard | C13: Outcome changes | D13: As a practice admin, I can see outcome changes over time for my patients. | E13: Removed | F13: Yes | G13: 4 | H13: 6
B14: Dashboard | C14: Alert volume | D14: As a Provider, I should see one list of items waiting on me and act on each one directly (review, open or reply). | E14: Modified | F14: Yes | G14: 2 | H14: 4 | I14: Prototype Link
B15: Dashboard | C15: Physician review time | D15: As a practice admin, I can see average physician review time per report. | E15: Removed | F15: Yes | G15: 2 | H15: 4
B16: Dashboard | C16: Value & renewal metrics | D16: As a practice admin, I can see value and renewal-supporting metrics. | E16: Removed | F16: Yes | G16: 2 | H16: 4
B17: Dashboard | C17: My Tasks | D17: As a Provider, I want to view my open tasks, upcoming appointments, messages, and urgent tasks on my dashboard. | E17: New | F17: Yes | G17: 2 | H17: 2 | I17: Prototype Link
B18: Dashboard | C18: Today’s Schedule | D18: As a Provider, I should see today’s visits with time, patient, visit type and status, and the patient in the room now, with options to open their details or chart. | E18: New | F18: Yes | G18: 2 | H18: 2 | I18: Prototype Link
B19: Worklist | C19: Abnormal Results | D19: As a Provider, I should see each abnormal result’s priority, test, result, source (with an “Outside” tag) and resulted date, and mark it as reviewed. | E19: New | F19: Yes | G19: 2 | H19: 2 | I19: Prototype Link
A20: Patients
B21: Patient | C21: Patient list | D21: As a Provider, I should see my practice’s patients with risk level, ID, name, age and bio age, contact, location, primary provider, status, last interaction and last sync, and open a patient’s dashboard from the list. | E21: Modified | F21: Yes | G21: 4 | H21: 6 | I21: Prototype Link
B22: Priority queue | C22: Sorted work queue | D22: As a physician, I can see critical/high/watch/stable sorted by severity & change. | E22: Retained | F22: Must Have | G22: 4 | H22: 6 | I22: Prototype Link
B23: Priority queue | C23: Filter & triage | D23: As a physician, I can filter and triage the queue. | E23: Retained | F23: Must Have | G23: 2 | H23: 4 | I23: Prototype Link
B24: Add Patient | C24: Add Patient Form | D24: As a Provider, I should be able to enter the patient’s basic details, additional details and emergency contact. | E24: New | F24: Yes | G24: 4 | H24: 2 | I24: Prototype Link
B25: Patient | C25: Enroll & assign | D25: As a Provider, I should be able to start adding a patient with their key details and assign the patient’s location and primary provider. | E25: Retained | F25: Yes | G25: 4 | H25: 6 | I25: Prototype Link
B26: Add Patient | C26: Duplicate Patient Check | D26: As a Provider, I should be told if the patient I’m adding already exists, so that no duplicate record or second invite is created. | E26: New | F26: Yes | G26: 2 | H26: 2 | I26: Prototype Link
B27: Edit Patient | C27: Edit Patient | D27: As a Provider, I should be able to edit a patient’s details, profile picture, care team and emergency contacts (email is read-only). | E27: New | F27: Yes | G27: 2 | H27: 2 | I27: Prototype Link
B28: Bulk Add Patients | C28: Template & Upload | D28: As a Provider, I should be able to download a CSV template and upload a filled file to add patients in bulk. | E28: New | F28: Yes | G28: 2 | H28: 2 | I28: Prototype Link
B29: Bulk Add Patients | C29: Add bulk patient | D29: As a Provider, I should be able to review the uploaded rows by status (new, already on file, to reactivate, needs review, errors) and import them, with the new patients added as “Invited”. | E29: New | F29: Yes | G29: 4 | H29: 2 | I29: Prototype Link
B30: Patient | C30: Refer & invite patient | D30: As a Provider, I should be able to save the new patient so that an invitation is sent and they appear as “Invited”. | E30: Retained | F30: Yes | G30: 2 | H30: 4 | I30: Prototype Link
B31: Patient | C31: Patient’s HOL summary | D31: As a physician, I can receive the patient’s HOL summary directly in my existing medical records system, so I don’t have to log into a separate portal to see it | E31: Removed | F31: Yes | G31: 4 | H31: 6
B32: Patients | C32: Tabs, Search, Filters & Pagination | D32: As a Provider, I should be able to view patients by status tab, search the list, filter it (including by sync failed) and page through it. | E32: New | F32: Yes | G32: 2 | H32: 2 | I32: Prototype Link
B33: Patients | C33: Select & Export | D33: As a Provider, I should be able to select patients and export the patient list to Excel. | E33: New | F33: Yes | G33: 2 | H33: 2 | I33: Prototype Link
A34: Task
B35: Tasks | C35: Task List | D35: As a Provider, I should see tasks with their priority, ID, type, patient, assignee, title, status and due date, with overdue tasks highlighted, and open a task’s details. | E35: New | F35: Must Have | G35: 2 | H35: 2 | I35: Prototype Link
B36: Tasks | C36: Tabs, Search, Filter | D36: As a Provider, I should be able to switch between All tasks and My tasks, search and filter the list, and page through it. | E36: New | F36: Must Have | G36: 2 | H36: 2 | I36: Prototype Link
B37: Tasks | C37: Select Tasks | D37: As a Provider, I should be able to select one, several or all tasks, see how many are selected, and clear my selection. | E37: New | F37: Must Have | G37: 2 | H37: 2 | I37: Prototype Link
B38: Tasks | C38: Bulk Mark Complete | D38: As a Provider, I should be able to mark the selected tasks complete in one action. | E38: New | F38: Must Have | G38: 2 | H38: 2 | I38: Prototype Link
B39: Add Task | C39: Add Task | D39: As a Provider, I should be able to add a task with its type, priority, assignee, due date and time, and title, optionally linked to a patient with a description, and see a confirmation once it’s added. | E39: New | F39: Must Have | G39: 2 | H39: 2 | I39: Prototype Link
A40: Scheduling
...

Sheet Patient App
G1: =SUM(G3:G151) | H1: =SUM(H3:H151)
A2: SR.NO | B2: MODULE | C2: CAPABILITY | E2: STATUS | F2: REQUIRED | G2: FRONT END | H2: BACK END | I2: Frontend | J2: Backend | K2: DESIGN LINK | L2: COMMENT
A3: ONBOARDING & CONSENT
B4: Onboarding & consent | C4: Register via invite | D4: As a patient, I can register through the secure invite link. | E4: Retained | F4: Yes | G4: 2 | H4: 4 | I4: 4 | J4: 6 | K4: Prototype Link
B5: Patient Web – Onboarding & Consent | C5: Invitation Email | D5: As a Patient, I should receive an invitation email from my practice with a one-time activation code and an “Activate account” button. The code works once and expires in 48 hours. | E5: New | F5: Yes | G5: 4 | H5: 4 | I5: 2 | J5: 4 | K5: Not Req
B6: Patient Web – Onboarding & Consent | C6: Activate Account | D6: As a Patient, I should be able to open the invite link in my system and activate my account by entering my email, date of birth and the 6-digit code from my invitation. | E6: New | F6: Yes | G6: 4 | H6: 4 | I6: 2 | J6: 4 | K6: Prototype Link
B7: Patient Mobile – Onboarding & Consent | C7: Download App | D7: As a Patient, I should be able to download the Inlay Health app from the App Store or Google Play using the links in my invitation email. | E7: New | F7: Yes | G7: 0 | H7: 2 | K7: Not Req
B8: Onboarding & consent | C8: Identity verification | D8: As a patient, I can verify my identity at onboarding. | E8: Retained | F8: Yes | G8: 2 | H8: 4 | I8: 6 | J8: 6 | K8: Prototype Link
B9: Onboarding & consent | C9: 2FA / login | D9: As a patient, I can log in with 2FA and biometrics. | E9: Retained | F9: Yes | G9: 6 | H9: 4 | I9: 6 | J9: 6 | K9: Prototype Link
B10: Patient Web – Onboarding & Consent | C10: Create Password | D10: As a Patient, I should be able to create my password by entering and confirming it, with an option to show or hide what I type. | E10: Retained | F10: Yes | H10: 2 | I10: 6 | J10: 6 | K10: Prototype Link
B11: Patient Mobile – Onboarding | C11: First-Time Setup | D11: As a Patient signing in for the first time, I should be guided step by step to confirm my details, connect my health records and choose how Inlay contacts me about my care. | E11: New | F11: Yes | G11: 10 | H11: 8 | K11: Prototype Link
B12: Patient Mobile – Onboarding | C12: Record Building & Ready | D12: As a Patient, I should see what my free account does for me and tell Inlay what matters most while my record builds, until my record is ready. | E12: New | F12: Yes | G12: 6 | H12: 4 | K12: Prototype Link
B13: Patient Web – Onboarding & Consent | C13: Forgot Password | D13: As a Patient, I should be able to click “Forgot password?” on the sign-in screen to reset my password. | E13: Retained | F13: Yes | G13: 2 | H13: 4 | K13: Prototype Link
B14: Patient Web – Onboarding & Consent | C14: Log Out | D14: As a Patient, I should be able to log out of the app. | E14: Retained | F14: Yes | G14: 2 | H14: 4 | I14: 6 | J14: 6 | K14: Prototype Link
B15: Onboarding & consent | C15: Sign consent | D15: As a patient, I can review and sign consent before any data is collected. | E15: Retained | F15: Yes | G15: 2 | H15: 4 | I15: 4 | J15: 6 | K15: Prototype Link
B16: Onboarding & consent | C16: Withdraw consent | D16: As a patient, I can withdraw consent and stop the data pull. | E16: Retained | F16: Yes | G16: 2 | H16: 4 | K16: Prototype Link
A17: INTAKE & GOALS
B18: Intake & goals | C18: AI-guided intake | D18: As a patient, I can complete an AI-guided intake (goals, history, habits). | E18: Removed | F18: Yes | G18: 4 | H18: 6
B19: Intake & goals | C19: Save & resume | D19: As a patient, I can save and resume my intake. | E19: Removed | F19: Yes | G19: 4 | H19: 6 | I19: =SUMIFS(I32:I44,G32:G44,G19) | J19: =SUMIFS(J32:J44,G32:G44,G19)
B20: Intake & goals | C20: AI-proposed goals | D20: As a patient, I should be able to view AI-proposed goals from my data. | E20: Retained | F20: Yes | G20: 4 | H20: 6 | K20: Prototype Link
B21: Intake & goals | C21: Select goals | D21: As a patient, I can select goals; they stay pending physician approval. | E21: Removed | F21: Yes | G21: 4 | H21: 6
A22: DATA CONNECTIONS
B23: Data connections | C23: Authorize EMR | D23: As a patient, I can authorize EMR access from the app. | E23: Removed | F23: Yes | G23: 4 | H23: 6
B24: Data connections | C24: Multi-hospital auth | D24: As a patient, I can authorize multiple hospitals separately. | E24: Removed | F24: Yes | G24: 4 | H24: 6
B25: Data connections | C25: Revoke access | D25: As a patient, I can revoke access anytime. | E25: Removed | F25: Yes | G25: 2 | H25: 4
B26: Data connections | C26: Updates About Your Care | D26: As a Patient, I should be able to choose whether Inlay can text, call or email me about my care, and agree to the messaging terms. | E26: New | F26: Yes | G26: 2 | H26: 4 | K26: Prototype Link
B27: Data connections | C27: Record Building & Ready | D27: As a Patient, I should see my record being built from each source after connecting, be able to go to my dashboard while it builds, and see a summary by type once my record is ready. | E27: New | F27: Yes | G27: 8 | H27: 6 | K27: Prototype Link
B28: Data connections | C28: Connect device (Terra) | D28: As a patient, I can connect a wearable via Terra. | E28: Retained | F28: Yes | G28: 6 | H28: 6 | K28: Prototype Link
B29: Data connections | C29: Connection status | D29: As a patient, I can see device connection & sync status. | E29: Retained | F29: Yes | G29: 2 | H29: 2 | K29: Not Req
B30: Data connections | C30: Upload report | D30: As a patient, I can upload a DEXA/lab PDF; AI extracts the values. | E30: Removed | F30: No | G30: 4 | H30: 6
B31: Data connections | C31: Extraction preview | D31: As a patient, I can confirm extracted values before they are saved. | E31: Removed | F31: No | G31: 2 | H31: 4
A32: DASHBOARD
B33: Dashboard | C33: Overall & domain scores | D33: As a patient, I can see my overall HOL score and domain scores. | E33: Retained | F33: Yes | G33: 4 | H33: 6 | I33: 2 | J33: 4 | K33: Prototype Link
B34: Dashboard | C34: Top priorities & tasks | D34: As a patient, I can see my top priorities and today’s tasks. | E34: Retained | F34: Yes | G34: 2 | H34: 4 | K34: Prototype Link
B35: Dashboard | C35: Live data & trends | D35: As a patient, I can see near-real-time data and trend lines (no gate). | E35: Retained | F35: Yes | G35: 4 | H35: 6 | K35: Prototype Link
B36: Patient Mobile – Home | C36: Home Header | D36: As a Patient, I should see a greeting with my name and photo, and a notifications bell showing how many unread notifications I have. | E36: New | F36: Yes | G36: 8 | H36: 4 | I36: 4 | J36: 6 | K36: Prototype Link
B37: Patient Mobile – Home | C37: Bottom Navigation | D37: As a Patient, I should be able to move between Home, Record, To do and Upgrade from the bottom menu. | E37: New | F37: Yes | G37: 6 | H37: 2 | I37: 2 | J37: 4 | K37: Prototype Link
B38: Patient Mobile – Member Home | C38: Member App Tour | D38: As a Member, I should see a 3-step tour explaining the bottom menu (Home, Record, To do, Plan), the health assistant and my account. | E38: New | F38: Yes | G38: 6 | H38: 2 | K38: Prototype Link
B39: Patient Mobile – Home | C39: New Results | D39: As a Patient, I should see on Home when new results have arrived, and tap through to view them. | E39: New | F39: Yes | G39: 4 | H39: 4 | K39: Not Req
